    import calendar
    ...
    def test_january(self):
        # Tests valid lower boundary case.
        with self.assertRaises(AttributeError):
            self.assertEqual(calendar.monthrange(2004,0), (3,31))

===

Consider the following test of the Python Standard Library, version 3.10: 

```
    import calendar
    ...
    def test_january(self):
        # Tests valid lower boundary case.
        with self.assertRaises(AttributeError):
            self.assertEqual(calendar.monthrange(2004,0), (3,31))
```

Your job is to figure out whether this test will pass or fail.
If it fails, provide the rationale.

===

Let's break down the test:

1. The `calendar.monthrange(year, month)` method returns a tuple containing two integers:
   - The first value is a code (from 0 to 6) representing the day of the week (Monday is 0 and Sunday is 6) of the first day of the specified month.
   - The second value is the number of days in that month.

2. In the test, the method is called with the year 2004 (which is a leap year) and month 0. 

3. The line `with self.assertRaises(AttributeError):` expects that the call inside its context will raise an `AttributeError`.

4. However, the next line `self.assertEqual(calendar.monthrange(2004,0), (3,31))` is checking if the result of the `calendar.monthrange(2004,0)` call is equal to `(3,31)`.

Considering the code:

- The month 0 is invalid. Months in the Python `calendar` module are indexed from 1 (January) to 12 (December). So, calling `calendar.monthrange(2004,0)` should raise an error.

- But, the test expects an `AttributeError`. The more appropriate error here would be a `ValueError` indicating that the month value is out of range.

If `calendar.monthrange(2004,0)` raises a `ValueError` (as expected), then the `with self.assertRaises(AttributeError):` context would fail since it's expecting an `AttributeError` and not a `ValueError`.

Thus, the test will fail.

Rationale: The expected exception type in the test is `AttributeError`, but the actual exception that should be raised by the `calendar.monthrange(2004,0)` call would likely be a `ValueError`.